Workbook

Sheet Assumptions
B1: DCF Valuation Model - Assumptions & Config
B2: All currency figures in $ millions unless noted. Edit only blue cells with yellow fill; everything else is formula-driven.
B3: Active Scenario (Bear / Base / Bull) | C3: Base | D3: Scenario # (1/2/3) | E3: =MATCH($C$3,Scenarios!$C$4:$E$4,0) -> 2
B4: Legend: | C4: Input | D4: Formula | E4: Link from other tab
B6: 1. General / Config
B7: Company Name | C7: Example Co. | D7: Example placeholder - replace
B8: Ticker | C8: EXCO | D8: Example placeholder - replace
B9: Units | C9: $ in millions | D9: Label only; shown in tab headers
B10: Last Actual Fiscal Year (Base Year) | C10: 2025 | D10: Projections run Base Year +1 through +5
B11: Valuation Date | C11: 46308 | D11: Example placeholder - replace
B13: 2. Company-Wide Valuation Inputs
B14: Tax Rate | C14: 0.25 | D14: Example placeholder - effective/marginal cash tax rate
B15: Discount Rate (WACC) | C15: =WACC!$C$23 -> 0.094714286 | D15: Example placeholder - replace with WACC build
B16: Terminal Growth Rate | C16: 0.025 | D16: Example placeholder - long-run nominal growth
B17: Check: Terminal Growth < WACC | C17: =IF(C16<C15,"OK","ERROR") -> OK
B19: 3. Segment Inputs (up to 8 segments)
B20: Segment Name | C20: Current Revenue ($mm) | D20: Projected Growth Rate (% / yr) | E20: Operating Margin (%) | F20: Notes / Source
B21: Products | C21: 1200 | D21: =Scenarios!$F$7 -> 0.06 | E21: =Scenarios!$F$17 -> 0.22 | F21: Example placeholder - replace with company data
B22: Services | C22: 650 | D22: =Scenarios!$F$8 -> 0.1 | E22: =Scenarios!$F$18 -> 0.3 | F22: Example placeholder - replace with company data
B23: Licensing & Other | C23: 150 | D23: =Scenarios!$F$9 -> 0.03 | E23: =Scenarios!$F$19 -> 0.08 | F23: Example placeholder - replace with company data
D24: =Scenarios!$F$10 -> 0 | E24: =Scenarios!$F$20 -> 0
D25: =Scenarios!$F$11 -> 0 | E25: =Scenarios!$F$21 -> 0
D26: =Scenarios!$F$12 -> 0 | E26: =Scenarios!$F$22 -> 0
D27: =Scenarios!$F$13 -> 0 | E27: =Scenarios!$F$23 -> 0
D28: =Scenarios!$F$14 -> 0 | E28: =Scenarios!$F$24 -> 0
B29: Total / Revenue-Weighted Average | C29: =SUM(C21:C28) -> 2000 | D29: =IF(C29=0,0,SUMPRODUCT(C21:C28,D21:D28)/C29) -> 0.07075 | E29: =IF(C29=0,0,SUMPRODUCT(C21:C28,E21:E28)/C29) -> 0.2355
B31: Model Notes
B32: 1. To add a segment, fill the next empty slot (rows 21-28); Segment_Revenue picks it up automatically. Blank slots calculate as zero.
B33: 2. Growth rate and operating margin are applied uniformly to all 5 projection years; base-year operating income = current revenue x operating margin.
B34: 3. Time-series tabs share one column layout: C = base year (actual), D:H = years 1-5. Link downstream tabs to the Total Company Summary block on Segment_Revenue.
B35: 4. Named ranges: CompanyName, Ticker, Units, BaseYear, ValuationDate, TaxRate, WACC, TerminalGrowth, Seg_Names, Seg_Revenue, Seg_Growth, Seg_Margin, FY_Labels, Period, Total_Revenue, Total_EBIT.
B36: 5. Add new driver sections (e.g. 4. Working Capital, 5. Capex & D&A) below this notes block.
B38: 4. Working Capital Drivers
B39: Fiscal Year | C39: =Segment_Revenue!C$4 -> FY2025A | D39: =Segment_Revenue!D$4 -> FY2026E | E39: =Segment_Revenue!E$4 -> FY2027E | F39: =Segment_Revenue!F$4 -> FY2028E | G39: =Segment_Revenue!G$4 -> FY2029E | H39: =Segment_Revenue!H$4 -> FY2030E | I39: Notes / Source
B40: COGS (% of Revenue) | C40: 0.55 | D40: 0.55 | E40: 0.55 | F40: 0.55 | G40: 0.55 | H40: 0.55 | I40: Drives COGS for DIO / DPO; example placeholder
B41: DSO - Days Sales Outstanding | C41: 45 | D41: =Scenarios!$F$27 -> 45 | E41: =Scenarios!$F$28 -> 44 | F41: =Scenarios!$F$29 -> 44 | G41: =Scenarios!$F$30 -> 43 | H41: =Scenarios!$F$31 -> 43 | I41: Receivables = DSO x Revenue / Days per Year
B42: DIO - Days Inventory Outstanding | C42: 60 | D42: =Scenarios!$F$32 -> 60 | E42: =Scenarios!$F$33 -> 58 | F42: =Scenarios!$F$34 -> 57 | G42: =Scenarios!$F$35 -> 56 | H42: =Scenarios!$F$36 -> 55 | I42: Inventory = DIO x COGS / Days per Year
B43: DPO - Days Payables Outstanding | C43: 40 | D43: =Scenarios!$F$37 -> 40 | E43: =Scenarios!$F$38 -> 40 | F43: =Scenarios!$F$39 -> 40 | G43: =Scenarios!$F$40 -> 40 | H43: =Scenarios!$F$41 -> 40 | I43: Payables = DPO x COGS / Days per Year
B44: Days per Year | C44: 365 | I44: Day-count basis for DSO / DIO / DPO
B45: Base-Year Balances ($mm) | C45: =Segment_Revenue!C$4 -> FY2025A
...

Sheet Segment_Revenue
B1: =CompanyName&" - Segment Revenue & Operating Income Build" -> Example Co. - Segment Revenue & Operating Income Build
B2: ="("&Units&"; all drivers link to the Assumptions tab)" -> ($ in millions; all drivers link to the Assumptions tab)
B4: Fiscal Year | C4: ="FY"&BaseYear&"A" -> FY2025A | D4: ="FY"&(BaseYear+D$5)&"E" -> FY2026E | E4: ="FY"&(BaseYear+E$5)&"E" -> FY2027E | F4: ="FY"&(BaseYear+F$5)&"E" -> FY2028E | G4: ="FY"&(BaseYear+G$5)&"E" -> FY2029E | H4: ="FY"&(BaseYear+H$5)&"E" -> FY2030E | I4: 5-Yr CAGR
B5: Projection Period (t) | C5: 0 | D5: =C5+1 -> 1 | E5: =D5+1 -> 2 | F5: =E5+1 -> 3 | G5: =F5+1 -> 4 | H5: =G5+1 -> 5
B7: Revenue by Segment
B8: =IF(Assumptions!$B21="","",Assumptions!$B21) -> Products | C8: =Assumptions!$C21 -> 1200 | D8: =C8*(1+Assumptions!$D21) -> 1272 | E8: =D8*(1+Assumptions!$D21) -> 1348.32 | F8: =E8*(1+Assumptions!$D21) -> 1429.2192 | G8: =F8*(1+Assumptions!$D21) -> 1514.9724 | H8: =G8*(1+Assumptions!$D21) -> 1605.8707 | I8: =IF(C8<=0,0,(H8/C8)^(1/$H$5)-1) -> 0.06
B9: =IF(Assumptions!$B22="","",Assumptions!$B22) -> Services | C9: =Assumptions!$C22 -> 650 | D9: =C9*(1+Assumptions!$D22) -> 715 | E9: =D9*(1+Assumptions!$D22) -> 786.5 | F9: =E9*(1+Assumptions!$D22) -> 865.15 | G9: =F9*(1+Assumptions!$D22) -> 951.665 | H9: =G9*(1+Assumptions!$D22) -> 1046.8315 | I9: =IF(C9<=0,0,(H9/C9)^(1/$H$5)-1) -> 0.1
B10: =IF(Assumptions!$B23="","",Assumptions!$B23) -> Licensing & Other | C10: =Assumptions!$C23 -> 150 | D10: =C10*(1+Assumptions!$D23) -> 154.5 | E10: =D10*(1+Assumptions!$D23) -> 159.135 | F10: =E10*(1+Assumptions!$D23) -> 163.90905 | G10: =F10*(1+Assumptions!$D23) -> 168.82632 | H10: =G10*(1+Assumptions!$D23) -> 173.89111 | I10: =IF(C10<=0,0,(H10/C10)^(1/$H$5)-1) -> 0.03
B11: =IF(Assumptions!$B24="","",Assumptions!$B24) | C11: =Assumptions!$C24 -> 0 | D11: =C11*(1+Assumptions!$D24) -> 0 | E11: =D11*(1+Assumptions!$D24) -> 0 | F11: =E11*(1+Assumptions!$D24) -> 0 | G11: =F11*(1+Assumptions!$D24) -> 0 | H11: =G11*(1+Assumptions!$D24) -> 0 | I11: =IF(C11<=0,0,(H11/C11)^(1/$H$5)-1) -> 0
B12: =IF(Assumptions!$B25="","",Assumptions!$B25) | C12: =Assumptions!$C25 -> 0 | D12: =C12*(1+Assumptions!$D25) -> 0 | E12: =D12*(1+Assumptions!$D25) -> 0 | F12: =E12*(1+Assumptions!$D25) -> 0 | G12: =F12*(1+Assumptions!$D25) -> 0 | H12: =G12*(1+Assumptions!$D25) -> 0 | I12: =IF(C12<=0,0,(H12/C12)^(1/$H$5)-1) -> 0
B13: =IF(Assumptions!$B26="","",Assumptions!$B26) | C13: =Assumptions!$C26 -> 0 | D13: =C13*(1+Assumptions!$D26) -> 0 | E13: =D13*(1+Assumptions!$D26) -> 0 | F13: =E13*(1+Assumptions!$D26) -> 0 | G13: =F13*(1+Assumptions!$D26) -> 0 | H13: =G13*(1+Assumptions!$D26) -> 0 | I13: =IF(C13<=0,0,(H13/C13)^(1/$H$5)-1) -> 0
B14: =IF(Assumptions!$B27="","",Assumptions!$B27) | C14: =Assumptions!$C27 -> 0 | D14: =C14*(1+Assumptions!$D27) -> 0 | E14: =D14*(1+Assumptions!$D27) -> 0 | F14: =E14*(1+Assumptions!$D27) -> 0 | G14: =F14*(1+Assumptions!$D27) -> 0 | H14: =G14*(1+Assumptions!$D27) -> 0 | I14: =IF(C14<=0,0,(H14/C14)^(1/$H$5)-1) -> 0
B15: =IF(Assumptions!$B28="","",Assumptions!$B28) | C15: =Assumptions!$C28 -> 0 | D15: =C15*(1+Assumptions!$D28) -> 0 | E15: =D15*(1+Assumptions!$D28) -> 0 | F15: =E15*(1+Assumptions!$D28) -> 0 | G15: =F15*(1+Assumptions!$D28) -> 0 | H15: =G15*(1+Assumptions!$D28) -> 0 | I15: =IF(C15<=0,0,(H15/C15)^(1/$H$5)-1) -> 0
B16: Total Revenue | C16: =SUM(C8:C15) -> 2000 | D16: =SUM(D8:D15) -> 2141.5 | E16: =SUM(E8:E15) -> 2293.955 | F16: =SUM(F8:F15) -> 2458.2782 | G16: =SUM(G8:G15) -> 2635.4637 | H16: =SUM(H8:H15) -> 2826.5933 | I16: =IF(C16<=0,0,(H16/C16)^(1/$H$5)-1) -> 0.071634449
B17: % Growth | D17: =IF(C16=0,0,D16/C16-1) -> 0.07075 | E17: =IF(D16=0,0,E16/D16-1) -> 0.071190754 | F17: =IF(E16=0,0,F16/E16-1) -> 0.071633162 | G17: =IF(F16=0,0,G16/F16-1) -> 0.072077042 | H17: =IF(G16=0,0,H16/G16-1) -> 0.072522203
B19: Operating Income by Segment
B20: =IF(Assumptions!$B21="","",Assumptions!$B21) -> Products | C20: =C8*Assumptions!$E21 -> 264 | D20: =D8*Assumptions!$E21 -> 279.84 | E20: =E8*Assumptions!$E21 -> 296.6304 | F20: =F8*Assumptions!$E21 -> 314.42822 | G20: =G8*Assumptions!$E21 -> 333.29392 | H20: =H8*Assumptions!$E21 -> 353.29155 | I20: =IF(C20<=0,0,(H20/C20)^(1/$H$5)-1) -> 0.06
B21: =IF(Assumptions!$B22="","",Assumptions!$B22) -> Services | C21: =C9*Assumptions!$E22 -> 195 | D21: =D9*Assumptions!$E22 -> 214.5 | E21: =E9*Assumptions!$E22 -> 235.95 | F21: =F9*Assumptions!$E22 -> 259.545 | G21: =G9*Assumptions!$E22 -> 285.4995 | H21: =H9*Assumptions!$E22 -> 314.04945 | I21: =IF(C21<=0,0,(H21/C21)^(1/$H$5)-1) -> 0.1
B22: =IF(Assumptions!$B23="","",Assumptions!$B23) -> Licensing & Other | C22: =C10*Assumptions!$E23 -> 12 | D22: =D10*Assumptions!$E23 -> 12.36 | E22: =E10*Assumptions!$E23 -> 12.7308 | F22: =F10*Assumptions!$E23 -> 13.112724 | G22: =G10*Assumptions!$E23 -> 13.506106 | H22: =H10*Assumptions!$E23 -> 13.911289 | I22: =IF(C22<=0,0,(H22/C22)^(1/$H$5)-1) -> 0.03
B23: =IF(Assumptions!$B24="","",Assumptions!$B24) | C23: =C11*Assumptions!$E24 -> 0 | D23: =D11*Assumptions!$E24 -> 0 | E23: =E11*Assumptions!$E24 -> 0 | F23: =F11*Assumptions!$E24 -> 0 | G23: =G11*Assumptions!$E24 -> 0 | H23: =H11*Assumptions!$E24 -> 0 | I23: =IF(C23<=0,0,(H23/C23)^(1/$H$5)-1) -> 0
B24: =IF(Assumptions!$B25="","",Assumptions!$B25) | C24: =C12*Assumptions!$E25 -> 0 | D24: =D12*Assumptions!$E25 -> 0 | E24: =E12*Assumptions!$E25 -> 0 | F24: =F12*Assumptions!$E25 -> 0 | G24: =G12*Assumptions!$E25 -> 0 | H24: =H12*Assumptions!$E25 -> 0 | I24: =IF(C24<=0,0,(H24/C24)^(1/$H$5)-1) -> 0
B25: =IF(Assumptions!$B26="","",Assumptions!$B26) | C25: =C13*Assumptions!$E26 -> 0 | D25: =D13*Assumptions!$E26 -> 0 | E25: =E13*Assumptions!$E26 -> 0 | F25: =F13*Assumptions!$E26 -> 0 | G25: =G13*Assumptions!$E26 -> 0 | H25: =H13*Assumptions!$E26 -> 0 | I25: =IF(C25<=0,0,(H25/C25)^(1/$H$5)-1) -> 0
B26: =IF(Assumptions!$B27="","",Assumptions!$B27) | C26: =C14*Assumptions!$E27 -> 0 | D26: =D14*Assumptions!$E27 -> 0 | E26: =E14*Assumptions!$E27 -> 0 | F26: =F14*Assumptions!$E27 -> 0 | G26: =G14*Assumptions!$E27 -> 0 | H26: =H14*Assumptions!$E27 -> 0 | I26: =IF(C26<=0,0,(H26/C26)^(1/$H$5)-1) -> 0
B27: =IF(Assumptions!$B28="","",Assumptions!$B28) | C27: =C15*Assumptions!$E28 -> 0 | D27: =D15*Assumptions!$E28 -> 0 | E27: =E15*Assumptions!$E28 -> 0 | F27: =F15*Assumptions!$E28 -> 0 | G27: =G15*Assumptions!$E28 -> 0 | H27: =H15*Assumptions!$E28 -> 0 | I27: =IF(C27<=0,0,(H27/C27)^(1/$H$5)-1) -> 0
B28: Total Operating Income | C28: =SUM(C20:C27) -> 471 | D28: =SUM(D20:D27) -> 506.7 | E28: =SUM(E20:E27) -> 545.3112 | F28: =SUM(F20:F27) -> 587.08595 | G28: =SUM(G20:G27) -> 632.29952 | H28: =SUM(H20:H27) -> 681.25229 | I28: =IF(C28<=0,0,(H28/C28)^(1/$H$5)-1) -> 0.076607532
B29: % Operating Margin | C29: =IF(C16=0,0,C28/C16) -> 0.2355 | D29: =IF(D16=0,0,D28/D16) -> 0.23660985 | E29: =IF(E16=0,0,E28/E16) -> 0.23771661 | F29: =IF(F16=0,0,F28/F16) -> 0.23881997 | G29: =IF(G16=0,0,G28/G16) -> 0.23991965 | H29: =IF(H16=0,0,H28/H16) -> 0.24101532
B31: Total Company Summary (link downstream tabs to these rows)
B32: Total Revenue | C32: =C16 -> 2000 | D32: =D16 -> 2141.5 | E32: =E16 -> 2293.955 | F32: =F16 -> 2458.2782 | G32: =G16 -> 2635.4637 | H32: =H16 -> 2826.5933 | I32: =IF(C32<=0,0,(H32/C32)^(1/$H$5)-1) -> 0.071634449
B33: % Growth | D33: =D17 -> 0.07075 | E33: =E17 -> 0.071190754 | F33: =F17 -> 0.071633162 | G33: =G17 -> 0.072077042 | H33: =H17 -> 0.072522203
B34: Total Operating Income (EBIT) | C34: =C28 -> 471 | D34: =D28 -> 506.7 | E34: =E28 -> 545.3112 | F34: =F28 -> 587.08595 | G34: =G28 -> 632.29952 | H34: =H28 -> 681.25229 | I34: =IF(C34<=0,0,(H34/C34)^(1/$H$5)-1) -> 0.076607532
B35: % Operating Margin | C35: =C29 -> 0.2355 | D35: =D29 -> 0.23660985 | E35: =E29 -> 0.23771661 | F35: =F29 -> 0.23881997 | G35: =G29 -> 0.23991965 | H35: =H29 -> 0.24101532
B37: Check: base-year revenue ties to Assumptions | C37: =IF(ABS(C32-Assumptions!$C$29)<0.001,"OK","ERROR") -> OK

Sheet Working_Capital
B1: =CompanyName&" - Working Capital Schedule" -> Example Co. - Working Capital Schedule
B2: ="("&Units&"; drivers link to the Assumptions and Segment_Revenue tabs)" -> ($ in millions; drivers link to the Assumptions and Segment_Revenue tabs)
B4: Fiscal Year | C4: =Segment_Revenue!C$4 -> FY2025A | D4: =Segment_Revenue!D$4 -> FY2026E | E4: =Segment_Revenue!E$4 -> FY2027E | F4: =Segment_Revenue!F$4 -> FY2028E | G4: =Segment_Revenue!G$4 -> FY2029E | H4: =Segment_Revenue!H$4 -> FY2030E
B5: Projection Period (t) | C5: =Segment_Revenue!C$5 -> 0 | D5: =Segment_Revenue!D$5 -> 1 | E5: =Segment_Revenue!E$5 -> 2 | F5: =Segment_Revenue!F$5 -> 3 | G5: =Segment_Revenue!G$5 -> 4 | H5: =Segment_Revenue!H$5 -> 5
B7: Drivers
B8: Total Revenue | C8: =Segment_Revenue!C32 -> 2000 | D8: =Segment_Revenue!D32 -> 2141.5 | E8: =Segment_Revenue!E32 -> 2293.955 | F8: =Segment_Revenue!F32 -> 2458.2782 | G8: =Segment_Revenue!G32 -> 2635.4637 | H8: =Segment_Revenue!H32 -> 2826.5933
B9: COGS (% of Revenue) | C9: =Assumptions!C40 -> 0.55 | D9: =Assumptions!D40 -> 0.55 | E9: =Assumptions!E40 -> 0.55 | F9: =Assumptions!F40 -> 0.55 | G9: =Assumptions!G40 -> 0.55 | H9: =Assumptions!H40 -> 0.55
B10: COGS | C10: =C8*C9 -> 1100 | D10: =D8*D9 -> 1177.825 | E10: =E8*E9 -> 1261.6753 | F10: =F8*F9 -> 1352.053 | G10: =G8*G9 -> 1449.505 | H10: =H8*H9 -> 1554.6263
B11: DSO (days) | C11: =Assumptions!C41 -> 45 | D11: =Assumptions!D41 -> 45 | E11: =Assumptions!E41 -> 44 | F11: =Assumptions!F41 -> 44 | G11: =Assumptions!G41 -> 43 | H11: =Assumptions!H41 -> 43
B12: DIO (days) | C12: =Assumptions!C42 -> 60 | D12: =Assumptions!D42 -> 60 | E12: =Assumptions!E42 -> 58 | F12: =Assumptions!F42 -> 57 | G12: =Assumptions!G42 -> 56 | H12: =Assumptions!H42 -> 55
B13: DPO (days) | C13: =Assumptions!C43 -> 40 | D13: =Assumptions!D43 -> 40 | E13: =Assumptions!E43 -> 40 | F13: =Assumptions!F43 -> 40 | G13: =Assumptions!G43 -> 40 | H13: =Assumptions!H43 -> 40
B15: Working Capital Balances
B16: Accounts Receivable | C16: =Assumptions!$C$46 -> 245 | D16: =D11*D8/Assumptions!$C$44 -> 264.02055 | E16: =E11*E8/Assumptions!$C$44 -> 276.53156 | F16: =F11*F8/Assumptions!$C$44 -> 296.34039 | G16: =G11*G8/Assumptions!$C$44 -> 310.47928 | H16: =H11*H8/Assumptions!$C$44 -> 332.99592
B17: Inventory | C17: =Assumptions!$C$47 -> 180 | D17: =D12*D10/Assumptions!$C$44 -> 193.61507 | E17: =E12*E10/Assumptions!$C$44 -> 200.48538 | F17: =F12*F10/Assumptions!$C$44 -> 211.14253 | G17: =G12*G10/Assumptions!$C$44 -> 222.38981 | H17: =H12*H10/Assumptions!$C$44 -> 234.25876
B18: Accounts Payable | C18: =Assumptions!$C$48 -> 120 | D18: =D13*D10/Assumptions!$C$44 -> 129.07671 | E18: =E13*E10/Assumptions!$C$44 -> 138.26578 | F18: =F13*F10/Assumptions!$C$44 -> 148.1702 | G18: =G13*G10/Assumptions!$C$44 -> 158.84987 | H18: =H13*H10/Assumptions!$C$44 -> 170.37001
B19: Net Working Capital (AR + Inventory - AP) | C19: =C16+C17-C18 -> 305 | D19: =D16+D17-D18 -> 328.5589 | E19: =E16+E17-E18 -> 338.75116 | F19: =F16+F17-F18 -> 359.31273 | G19: =G16+G17-G18 -> 374.01923 | H19: =H16+H17-H18 -> 396.88468
B20: NWC (% of Revenue) | C20: =IF(C8=0,0,C19/C8) -> 0.1525 | D20: =IF(D8=0,0,D19/D8) -> 0.15342466 | E20: =IF(E8=0,0,E19/E8) -> 0.14767123 | F20: =IF(F8=0,0,F19/F8) -> 0.14616438 | G20: =IF(G8=0,0,G19/G8) -> 0.14191781 | H20: =IF(H8=0,0,H19/H8) -> 0.14041096
B22: Change in Net Working Capital (link FCF tab to this row)
B23: Change in NWC (increase = cash outflow) | D23: =D19-C19 -> 23.558904 | E23: =E19-D19 -> 10.192259 | F23: =F19-E19 -> 20.561562 | G23: =G19-F19 -> 14.706503 | H23: =H19-G19 -> 22.865448

Sheet Capex
B1: =CompanyName&" - Capital Expenditure Schedule" -> Example Co. - Capital Expenditure Schedule
B2: ="("&Units&"; drivers link to the Assumptions and Segment_Revenue tabs)" -> ($ in millions; drivers link to the Assumptions and Segment_Revenue tabs)
B4: Fiscal Year | C4: =Segment_Revenue!C$4 -> FY2025A | D4: =Segment_Revenue!D$4 -> FY2026E | E4: =Segment_Revenue!E$4 -> FY2027E | F4: =Segment_Revenue!F$4 -> FY2028E | G4: =Segment_Revenue!G$4 -> FY2029E | H4: =Segment_Revenue!H$4 -> FY2030E
B5: Projection Period (t) | C5: =Segment_Revenue!C$5 -> 0 | D5: =Segment_Revenue!D$5 -> 1 | E5: =Segment_Revenue!E$5 -> 2 | F5: =Segment_Revenue!F$5 -> 3 | G5: =Segment_Revenue!G$5 -> 4 | H5: =Segment_Revenue!H$5 -> 5
B7: Maintenance Capex
B8: Total Revenue | C8: =Segment_Revenue!C32 -> 2000 | D8: =Segment_Revenue!D32 -> 2141.5 | E8: =Segment_Revenue!E32 -> 2293.955 | F8: =Segment_Revenue!F32 -> 2458.2782 | G8: =Segment_Revenue!G32 -> 2635.4637 | H8: =Segment_Revenue!H32 -> 2826.5933
B9: Maintenance Capex (% of Revenue) | D9: =Assumptions!$C$51 -> 0.03 | E9: =Assumptions!$C$51 -> 0.03 | F9: =Assumptions!$C$51 -> 0.03 | G9: =Assumptions!$C$51 -> 0.03 | H9: =Assumptions!$C$51 -> 0.03
B10: Maintenance Capex | D10: =D8*D9 -> 64.245 | E10: =E8*E9 -> 68.81865 | F10: =F8*F9 -> 73.748347 | G10: =G8*G9 -> 79.06391 | H10: =H8*H9 -> 84.797799
B12: Incremental Revenue by Segment (year-over-year increase)
B13: =IF(Assumptions!$B21="","",Assumptions!$B21) -> Products | D13: =Segment_Revenue!D8-Segment_Revenue!C8 -> 72 | E13: =Segment_Revenue!E8-Segment_Revenue!D8 -> 76.32 | F13: =Segment_Revenue!F8-Segment_Revenue!E8 -> 80.8992 | G13: =Segment_Revenue!G8-Segment_Revenue!F8 -> 85.753152 | H13: =Segment_Revenue!H8-Segment_Revenue!G8 -> 90.898341
B14: =IF(Assumptions!$B22="","",Assumptions!$B22) -> Services | D14: =Segment_Revenue!D9-Segment_Revenue!C9 -> 65 | E14: =Segment_Revenue!E9-Segment_Revenue!D9 -> 71.5 | F14: =Segment_Revenue!F9-Segment_Revenue!E9 -> 78.65 | G14: =Segment_Revenue!G9-Segment_Revenue!F9 -> 86.515 | H14: =Segment_Revenue!H9-Segment_Revenue!G9 -> 95.1665
B15: =IF(Assumptions!$B23="","",Assumptions!$B23) -> Licensing & Other | D15: =Segment_Revenue!D10-Segment_Revenue!C10 -> 4.5 | E15: =Segment_Revenue!E10-Segment_Revenue!D10 -> 4.635 | F15: =Segment_Revenue!F10-Segment_Revenue!E10 -> 4.77405 | G15: =Segment_Revenue!G10-Segment_Revenue!F10 -> 4.9172715 | H15: =Segment_Revenue!H10-Segment_Revenue!G10 -> 5.0647896
B16: =IF(Assumptions!$B24="","",Assumptions!$B24) | D16: =Segment_Revenue!D11-Segment_Revenue!C11 -> 0 | E16: =Segment_Revenue!E11-Segment_Revenue!D11 -> 0 | F16: =Segment_Revenue!F11-Segment_Revenue!E11 -> 0 | G16: =Segment_Revenue!G11-Segment_Revenue!F11 -> 0 | H16: =Segment_Revenue!H11-Segment_Revenue!G11 -> 0
B17: =IF(Assumptions!$B25="","",Assumptions!$B25) | D17: =Segment_Revenue!D12-Segment_Revenue!C12 -> 0 | E17: =Segment_Revenue!E12-Segment_Revenue!D12 -> 0 | F17: =Segment_Revenue!F12-Segment_Revenue!E12 -> 0 | G17: =Segment_Revenue!G12-Segment_Revenue!F12 -> 0 | H17: =Segment_Revenue!H12-Segment_Revenue!G12 -> 0
B18: =IF(Assumptions!$B26="","",Assumptions!$B26) | D18: =Segment_Revenue!D13-Segment_Revenue!C13 -> 0 | E18: =Segment_Revenue!E13-Segment_Revenue!D13 -> 0 | F18: =Segment_Revenue!F13-Segment_Revenue!E13 -> 0 | G18: =Segment_Revenue!G13-Segment_Revenue!F13 -> 0 | H18: =Segment_Revenue!H13-Segment_Revenue!G13 -> 0
B19: =IF(Assumptions!$B27="","",Assumptions!$B27) | D19: =Segment_Revenue!D14-Segment_Revenue!C14 -> 0 | E19: =Segment_Revenue!E14-Segment_Revenue!D14 -> 0 | F19: =Segment_Revenue!F14-Segment_Revenue!E14 -> 0 | G19: =Segment_Revenue!G14-Segment_Revenue!F14 -> 0 | H19: =Segment_Revenue!H14-Segment_Revenue!G14 -> 0
B20: =IF(Assumptions!$B28="","",Assumptions!$B28) | D20: =Segment_Revenue!D15-Segment_Revenue!C15 -> 0 | E20: =Segment_Revenue!E15-Segment_Revenue!D15 -> 0 | F20: =Segment_Revenue!F15-Segment_Revenue!E15 -> 0 | G20: =Segment_Revenue!G15-Segment_Revenue!F15 -> 0 | H20: =Segment_Revenue!H15-Segment_Revenue!G15 -> 0
B21: Total Incremental Revenue | D21: =SUM(D13:D20) -> 141.5 | E21: =SUM(E13:E20) -> 152.455 | F21: =SUM(F13:F20) -> 164.32325 | G21: =SUM(G13:G20) -> 177.18542 | H21: =SUM(H13:H20) -> 191.12963
B23: Growth Capex by Segment (intensity x MAX(0, incremental revenue))
B24: =IF(Assumptions!$B21="","",Assumptions!$B21) -> Products | D24: =MAX(0,D13)*Assumptions!$C$53 -> 18 | E24: =MAX(0,E13)*Assumptions!$C$53 -> 19.08 | F24: =MAX(0,F13)*Assumptions!$C$53 -> 20.2248 | G24: =MAX(0,G13)*Assumptions!$C$53 -> 21.438288 | H24: =MAX(0,H13)*Assumptions!$C$53 -> 22.724585
B25: =IF(Assumptions!$B22="","",Assumptions!$B22) -> Services | D25: =MAX(0,D14)*Assumptions!$C$54 -> 9.75 | E25: =MAX(0,E14)*Assumptions!$C$54 -> 10.725 | F25: =MAX(0,F14)*Assumptions!$C$54 -> 11.7975 | G25: =MAX(0,G14)*Assumptions!$C$54 -> 12.97725 | H25: =MAX(0,H14)*Assumptions!$C$54 -> 14.274975
B26: =IF(Assumptions!$B23="","",Assumptions!$B23) -> Licensing & Other | D26: =MAX(0,D15)*Assumptions!$C$55 -> 0.45 | E26: =MAX(0,E15)*Assumptions!$C$55 -> 0.4635 | F26: =MAX(0,F15)*Assumptions!$C$55 -> 0.477405 | G26: =MAX(0,G15)*Assumptions!$C$55 -> 0.49172715 | H26: =MAX(0,H15)*Assumptions!$C$55 -> 0.50647896
B27: =IF(Assumptions!$B24="","",Assumptions!$B24) | D27: =MAX(0,D16)*Assumptions!$C$56 -> 0 | E27: =MAX(0,E16)*Assumptions!$C$56 -> 0 | F27: =MAX(0,F16)*Assumptions!$C$56 -> 0 | G27: =MAX(0,G16)*Assumptions!$C$56 -> 0 | H27: =MAX(0,H16)*Assumptions!$C$56 -> 0
B28: =IF(Assumptions!$B25="","",Assumptions!$B25) | D28: =MAX(0,D17)*Assumptions!$C$57 -> 0 | E28: =MAX(0,E17)*Assumptions!$C$57 -> 0 | F28: =MAX(0,F17)*Assumptions!$C$57 -> 0 | G28: =MAX(0,G17)*Assumptions!$C$57 -> 0 | H28: =MAX(0,H17)*Assumptions!$C$57 -> 0
B29: =IF(Assumptions!$B26="","",Assumptions!$B26) | D29: =MAX(0,D18)*Assumptions!$C$58 -> 0 | E29: =MAX(0,E18)*Assumptions!$C$58 -> 0 | F29: =MAX(0,F18)*Assumptions!$C$58 -> 0 | G29: =MAX(0,G18)*Assumptions!$C$58 -> 0 | H29: =MAX(0,H18)*Assumptions!$C$58 -> 0
B30: =IF(Assumptions!$B27="","",Assumptions!$B27) | D30: =MAX(0,D19)*Assumptions!$C$59 -> 0 | E30: =MAX(0,E19)*Assumptions!$C$59 -> 0 | F30: =MAX(0,F19)*Assumptions!$C$59 -> 0 | G30: =MAX(0,G19)*Assumptions!$C$59 -> 0 | H30: =MAX(0,H19)*Assumptions!$C$59 -> 0
B31: =IF(Assumptions!$B28="","",Assumptions!$B28) | D31: =MAX(0,D20)*Assumptions!$C$60 -> 0 | E31: =MAX(0,E20)*Assumptions!$C$60 -> 0 | F31: =MAX(0,F20)*Assumptions!$C$60 -> 0 | G31: =MAX(0,G20)*Assumptions!$C$60 -> 0 | H31: =MAX(0,H20)*Assumptions!$C$60 -> 0
B32: Total Growth Capex | D32: =SUM(D24:D31) -> 28.2 | E32: =SUM(E24:E31) -> 30.2685 | F32: =SUM(F24:F31) -> 32.499705 | G32: =SUM(G24:G31) -> 34.907265 | H32: =SUM(H24:H31) -> 37.506039
B34: Total Capex (link FCF tab to the Total Capex row)
B35: Maintenance Capex | D35: =D10 -> 64.245 | E35: =E10 -> 68.81865 | F35: =F10 -> 73.748347 | G35: =G10 -> 79.06391 | H35: =H10 -> 84.797799
B36: Growth Capex | D36: =D32 -> 28.2 | E36: =E32 -> 30.2685 | F36: =F32 -> 32.499705 | G36: =G32 -> 34.907265 | H36: =H32 -> 37.506039
B37: Total Capex (positive = cash outflow) | D37: =D35+D36 -> 92.445 | E37: =E35+E36 -> 99.08715 | F37: =F35+F36 -> 106.24805 | G37: =G35+G36 -> 113.97118 | H37: =H35+H36 -> 122.30384
B38: Total Capex (% of Revenue) | D38: =IF(D8=0,0,D37/D8) -> 0.04316834 | E38: =IF(E8=0,0,E37/E8) -> 0.043194897 | F38: =IF(F8=0,0,F37/F8) -> 0.043220515 | G38: =IF(G8=0,0,G37/G8) -> 0.043245208 | H38: =IF(H8=0,0,H37/H8) -> 0.04326899

Sheet WACC
B1: =CompanyName&" - WACC Build" -> Example Co. - WACC Build
B2: ="("&Units&"; inputs link to the Assumptions tab)" -> ($ in millions; inputs link to the Assumptions tab)
B4: Inputs (linked from Assumptions)
B5: Risk-Free Rate | C5: =Assumptions!$C$69 -> 0.0425
B6: Equity Risk Premium | C6: =Assumptions!$C$70 -> 0.055
B7: Levered Beta | C7: =Assumptions!$C$71 -> 1.1
B8: Pre-Tax Cost of Debt | C8: =Assumptions!$C$72 -> 0.06
B9: Tax Rate | C9: =Assumptions!$C$14 -> 0.25
B10: Market Capitalization ($mm) | C10: =Assumptions!$C$73 -> 6000
B11: Total Debt ($mm) | C11: =Assumptions!$C$74 -> 1000
B13: Cost of Capital
B14: Cost of Equity (CAPM: Rf + Beta x ERP) | C14: =C5+C7*C6 -> 0.103
B15: After-Tax Cost of Debt (Kd x (1 - Tax)) | C15: =C8*(1-C9) -> 0.045
B17: Capital Structure
B18: Total Capitalization (Market Cap + Debt) | C18: =C10+C11 -> 7000
B19: Equity Weight (E / (D + E)) | C19: =IF(C18=0,0,C10/C18) -> 0.85714286
B20: Debt Weight (D / (D + E)) | C20: =IF(C18=0,0,C11/C18) -> 0.14285714
B22: Weighted Average Cost of Capital
B23: WACC (discount rate used by the model) | C23: =C19*C14+C20*C15 -> 0.094714286

Sheet DCF
B1: =CompanyName&" - Discounted Cash Flow Valuation" -> Example Co. - Discounted Cash Flow Valuation
B2: ="("&Units&"; drivers link to the Assumptions and Segment_Revenue tabs)" -> ($ in millions; drivers link to the Assumptions and Segment_Revenue tabs)
B4: Fiscal Year | C4: =Segment_Revenue!C$4 -> FY2025A | D4: =Segment_Revenue!D$4 -> FY2026E | E4: =Segment_Revenue!E$4 -> FY2027E | F4: =Segment_Revenue!F$4 -> FY2028E | G4: =Segment_Revenue!G$4 -> FY2029E | H4: =Segment_Revenue!H$4 -> FY2030E
B5: Projection Period (t) | C5: =Segment_Revenue!C$5 -> 0 | D5: =Segment_Revenue!D$5 -> 1 | E5: =Segment_Revenue!E$5 -> 2 | F5: =Segment_Revenue!F$5 -> 3 | G5: =Segment_Revenue!G$5 -> 4 | H5: =Segment_Revenue!H$5 -> 5
B7: Unlevered Free Cash Flow
B8: EBIT | D8: =Segment_Revenue!D34 -> 506.7 | E8: =Segment_Revenue!E34 -> 545.3112 | F8: =Segment_Revenue!F34 -> 587.08595 | G8: =Segment_Revenue!G34 -> 632.29952 | H8: =Segment_Revenue!H34 -> 681.25229
B9: Less: Taxes (EBIT x Tax Rate) | D9: =-D8*Assumptions!$C$14 -> -126.675 | E9: =-E8*Assumptions!$C$14 -> -136.3278 | F9: =-F8*Assumptions!$C$14 -> -146.77149 | G9: =-G8*Assumptions!$C$14 -> -158.07488 | H9: =-H8*Assumptions!$C$14 -> -170.31307
B10: Plus: D&A (Revenue x D&A %) | D10: =Segment_Revenue!D32*Assumptions!$C$77 -> 74.9525 | E10: =Segment_Revenue!E32*Assumptions!$C$77 -> 80.288425 | F10: =Segment_Revenue!F32*Assumptions!$C$77 -> 86.039739 | G10: =Segment_Revenue!G32*Assumptions!$C$77 -> 92.241229 | H10: =Segment_Revenue!H32*Assumptions!$C$77 -> 98.930766
B11: Less: Total Capex | D11: =-Capex!D37 -> -92.445 | E11: =-Capex!E37 -> -99.08715 | F11: =-Capex!F37 -> -106.24805 | G11: =-Capex!G37 -> -113.97118 | H11: =-Capex!H37 -> -122.30384
B12: Less: Change in NWC | D12: =-Working_Capital!D23 -> -23.558904 | E12: =-Working_Capital!E23 -> -10.192259 | F12: =-Working_Capital!F23 -> -20.561562 | G12: =-Working_Capital!G23 -> -14.706503 | H12: =-Working_Capital!H23 -> -22.865448
B13: Unlevered Free Cash Flow | D13: =SUM(D8:D12) -> 338.9736 | E13: =SUM(E8:E12) -> 379.99242 | F13: =SUM(F8:F12) -> 399.54459 | G13: =SUM(G8:G12) -> 437.78819 | H13: =SUM(H8:H12) -> 464.7007
B15: Discounting
B16: Discount Rate (WACC) | C16: =Assumptions!$C$15 -> 0.094714286
B17: Mid-Year Convention (1 = mid-year, 0 = end-of-year) | C17: =Assumptions!$C$82 -> 1
B18: Discount Period (t - 0.5 x toggle) | D18: =D$5-0.5*$C$17 -> 0.5 | E18: =E$5-0.5*$C$17 -> 1.5 | F18: =F$5-0.5*$C$17 -> 2.5 | G18: =G$5-0.5*$C$17 -> 3.5 | H18: =H$5-0.5*$C$17 -> 4.5
B19: Discount Factor (1 / (1 + WACC)^period) | D19: =1/(1+$C$16)^D18 -> 0.95576166 | E19: =1/(1+$C$16)^E18 -> 0.87306951 | F19: =1/(1+$C$16)^F18 -> 0.79753185 | G19: =1/(1+$C$16)^G18 -> 0.72852968 | H19: =1/(1+$C$16)^H18 -> 0.66549756
B20: PV of Unlevered FCF | D20: =D13*D19 -> 323.97797 | E20: =E13*E19 -> 331.75979 | F20: =F13*F19 -> 318.64953 | G20: =G13*G19 -> 318.94169 | H20: =H13*H19 -> 309.25718
B21: Sum of PV of Unlevered FCF | C21: =SUM(D20:H20) -> 1602.5862
B23: Terminal Value & Valuation
C24: Perpetuity Growth | D24: Exit Multiple
B25: Terminal-Year Unlevered FCF | C25: =H13 -> 464.7007
B26: Terminal Growth Rate | C26: =Assumptions!$C$78 -> 0.025
B27: Terminal-Year EBITDA (EBIT + D&A) | D27: =H8+H10 -> 780.18306
B28: Exit EV/EBITDA Multiple | D28: =Assumptions!$C$79 -> 12
B29: Terminal Value | C29: =IF($C$16<=C26,0,C25*(1+C26)/($C$16-C26)) -> 6832.4334 | D29: =D27*D28 -> 9362.1967
B30: Terminal Discount Period (end of final year) | C30: =$H$5 -> 5 | D30: =$H$5 -> 5
B31: Terminal Discount Factor | C31: =1/(1+$C$16)^C30 -> 0.63605705 | D31: =1/(1+$C$16)^D30 -> 0.63605705
B32: PV of Terminal Value | C32: =C29*C31 -> 4345.8175 | D32: =D29*D31 -> 5954.8912
B33: Plus: Sum of PV of Unlevered FCF | C33: =$C$21 -> 1602.5862 | D33: =$C$21 -> 1602.5862
B34: Enterprise Value | C34: =C32+C33 -> 5948.4036 | D34: =D32+D33 -> 7557.4774
B35: Less: Net Debt | C35: =-Assumptions!$C$80 -> -800 | D35: =-Assumptions!$C$80 -> -800
B36: Equity Value | C36: =C34+C35 -> 5148.4036 | D36: =D34+D35 -> 6757.4774
B37: Diluted Shares Outstanding (mm) | C37: =Assumptions!$C$81 -> 150 | D37: =Assumptions!$C$81 -> 150
B38: Implied Share Price ($ per share) - OUTPUT | C38: =IF(C37=0,0,C36/C37) -> 34.322691 | D38: =IF(D37=0,0,D36/D37) -> 45.049849
B40: Cross-Checks
B41: PV of Terminal Value (% of Enterprise Value) | C41: =IF(C34=0,0,C32/C34) -> 0.7305855 | D41: =IF(D34=0,0,D32/D34) -> 0.78794695
B42: Implied Exit EV/EBITDA (from perpetuity method) | C42: =IF(D27=0,0,C29/D27) -> 8.7574747
B43: Implied Perpetual Growth (from exit multiple method) | D43: =IF(D29+C25=0,0,(D29*$C$16-C25)/(D29+C25)) -> 0.042946726

Sheet Scenarios
B1: =CompanyName&" - Scenarios" -> Example Co. - Scenarios
B2: ="(Edit Bear / Base / Bull inputs; Live = active case: "&Assumptions!$C$3&")" -> (Edit Bear / Base / Bull inputs; Live = active case: Base)
B4: Driver | C4: Bear | D4: Base | E4: Bull | F4: Live
B6: Segment Growth Rate (% / yr)
B7: =IF(Assumptions!$B21="","",Assumptions!$B21) -> Products | C7: 0.04 | D7: 0.06 | E7: 0.08 | F7: =CHOOSE(Assumptions!$E$3,C7,D7,E7) -> 0.06
B8: =IF(Assumptions!$B22="","",Assumptions!$B22) -> Services | C8: 0.08 | D8: 0.1 | E8: 0.12 | F8: =CHOOSE(Assumptions!$E$3,C8,D8,E8) -> 0.1
B9: =IF(Assumptions!$B23="","",Assumptions!$B23) -> Licensing & Other | C9: 0.01 | D9: 0.03 | E9: 0.05 | F9: =CHOOSE(Assumptions!$E$3,C9,D9,E9) -> 0.03
B10: =IF(Assumptions!$B24="","",Assumptions!$B24) | F10: =CHOOSE(Assumptions!$E$3,C10,D10,E10) -> 0
B11: =IF(Assumptions!$B25="","",Assumptions!$B25) | F11: =CHOOSE(Assumptions!$E$3,C11,D11,E11) -> 0
B12: =IF(Assumptions!$B26="","",Assumptions!$B26) | F12: =CHOOSE(Assumptions!$E$3,C12,D12,E12) -> 0
B13: =IF(Assumptions!$B27="","",Assumptions!$B27) | F13: =CHOOSE(Assumptions!$E$3,C13,D13,E13) -> 0
B14: =IF(Assumptions!$B28="","",Assumptions!$B28) | F14: =CHOOSE(Assumptions!$E$3,C14,D14,E14) -> 0
B16: Segment Operating Margin (%)
B17: =IF(Assumptions!$B21="","",Assumptions!$B21) -> Products | C17: 0.2 | D17: 0.22 | E17: 0.24 | F17: =CHOOSE(Assumptions!$E$3,C17,D17,E17) -> 0.22
B18: =IF(Assumptions!$B22="","",Assumptions!$B22) -> Services | C18: 0.28 | D18: 0.3 | E18: 0.32 | F18: =CHOOSE(Assumptions!$E$3,C18,D18,E18) -> 0.3
B19: =IF(Assumptions!$B23="","",Assumptions!$B23) -> Licensing & Other | C19: 0.06 | D19: 0.08 | E19: 0.1 | F19: =CHOOSE(Assumptions!$E$3,C19,D19,E19) -> 0.08
B20: =IF(Assumptions!$B24="","",Assumptions!$B24) | F20: =CHOOSE(Assumptions!$E$3,C20,D20,E20) -> 0
B21: =IF(Assumptions!$B25="","",Assumptions!$B25) | F21: =CHOOSE(Assumptions!$E$3,C21,D21,E21) -> 0
B22: =IF(Assumptions!$B26="","",Assumptions!$B26) | F22: =CHOOSE(Assumptions!$E$3,C22,D22,E22) -> 0
B23: =IF(Assumptions!$B27="","",Assumptions!$B27) | F23: =CHOOSE(Assumptions!$E$3,C23,D23,E23) -> 0
B24: =IF(Assumptions!$B28="","",Assumptions!$B28) | F24: =CHOOSE(Assumptions!$E$3,C24,D24,E24) -> 0
B26: Working Capital Days (projection years)
B27: ="DSO - "&Segment_Revenue!D$4 -> DSO - FY2026E | C27: 50 | D27: 45 | E27: 40 | F27: =CHOOSE(Assumptions!$E$3,C27,D27,E27) -> 45
B28: ="DSO - "&Segment_Revenue!E$4 -> DSO - FY2027E | C28: 49 | D28: 44 | E28: 39 | F28: =CHOOSE(Assumptions!$E$3,C28,D28,E28) -> 44
B29: ="DSO - "&Segment_Revenue!F$4 -> DSO - FY2028E | C29: 49 | D29: 44 | E29: 39 | F29: =CHOOSE(Assumptions!$E$3,C29,D29,E29) -> 44
B30: ="DSO - "&Segment_Revenue!G$4 -> DSO - FY2029E | C30: 48 | D30: 43 | E30: 38 | F30: =CHOOSE(Assumptions!$E$3,C30,D30,E30) -> 43
B31: ="DSO - "&Segment_Revenue!H$4 -> DSO - FY2030E | C31: 48 | D31: 43 | E31: 38 | F31: =CHOOSE(Assumptions!$E$3,C31,D31,E31) -> 43
B32: ="DIO - "&Segment_Revenue!D$4 -> DIO - FY2026E | C32: 65 | D32: 60 | E32: 55 | F32: =CHOOSE(Assumptions!$E$3,C32,D32,E32) -> 60
B33: ="DIO - "&Segment_Revenue!E$4 -> DIO - FY2027E | C33: 63 | D33: 58 | E33: 53 | F33: =CHOOSE(Assumptions!$E$3,C33,D33,E33) -> 58
B34: ="DIO - "&Segment_Revenue!F$4 -> DIO - FY2028E | C34: 62 | D34: 57 | E34: 52 | F34: =CHOOSE(Assumptions!$E$3,C34,D34,E34) -> 57
B35: ="DIO - "&Segment_Revenue!G$4 -> DIO - FY2029E | C35: 61 | D35: 56 | E35: 51 | F35: =CHOOSE(Assumptions!$E$3,C35,D35,E35) -> 56
B36: ="DIO - "&Segment_Revenue!H$4 -> DIO - FY2030E | C36: 60 | D36: 55 | E36: 50 | F36: =CHOOSE(Assumptions!$E$3,C36,D36,E36) -> 55
B37: ="DPO - "&Segment_Revenue!D$4 -> DPO - FY2026E | C37: 35 | D37: 40 | E37: 45 | F37: =CHOOSE(Assumptions!$E$3,C37,D37,E37) -> 40
B38: ="DPO - "&Segment_Revenue!E$4 -> DPO - FY2027E | C38: 35 | D38: 40 | E38: 45 | F38: =CHOOSE(Assumptions!$E$3,C38,D38,E38) -> 40
B39: ="DPO - "&Segment_Revenue!F$4 -> DPO - FY2028E | C39: 35 | D39: 40 | E39: 45 | F39: =CHOOSE(Assumptions!$E$3,C39,D39,E39) -> 40
B40: ="DPO - "&Segment_Revenue!G$4 -> DPO - FY2029E | C40: 35 | D40: 40 | E40: 45 | F40: =CHOOSE(Assumptions!$E$3,C40,D40,E40) -> 40
B41: ="DPO - "&Segment_Revenue!H$4 -> DPO - FY2030E | C41: 35 | D41: 40 | E41: 45 | F41: =CHOOSE(Assumptions!$E$3,C41,D41,E41) -> 40
B43: Capex, WACC & Terminal Value
B44: Maintenance Capex (% of Revenue) | C44: 0.035 | D44: 0.03 | E44: 0.025 | F44: =CHOOSE(Assumptions!$E$3,C44,D44,E44) -> 0.03
B45: Levered Beta | C45: 1.2 | D45: 1.1 | E45: 1 | F45: =CHOOSE(Assumptions!$E$3,C45,D45,E45) -> 1.1
...

Sheet Sensitivity
B1: =CompanyName&" - Sensitivity Analysis" -> Example Co. - Sensitivity Analysis
B2: ="(Implied share price, $ per share; centered on the live "&Assumptions!$C$3&" case)" -> (Implied share price, $ per share; centered on the live Base case)
B4: Grid Steps
B5: WACC Step | C5: 0.005
B6: Terminal Growth Step | C6: 0.005
B7: Exit Multiple Step | C7: 1
B9: Implied Share Price - Perpetuity Growth Method: WACC vs. Terminal Growth
B10: WACC \ Terminal Growth | C10: =$E$10-2*$C$6 -> 0.015 | D10: =$E$10-1*$C$6 -> 0.02 | E10: =DCF!$C$26 -> 0.025 | F10: =$E$10+1*$C$6 -> 0.03 | G10: =$E$10+2*$C$6 -> 0.035
B11: =$B$13-2*$C$5 -> 0.084714286 | C11: =IF(OR($B11<=C$10,DCF!$C$37=0),0,(SUMPRODUCT(DCF!$D$13:$H$13/(1+$B11)^DCF!$D$18:$H$18)+DCF!$C$25*(1+C$10)/($B11-C$10)/(1+$B11)^DCF!$C$30+DCF!$C$35)/DCF!$C$37) -> 35.6333 | D11: =IF(OR($B11<=D$10,DCF!$C$37=0),0,(SUMPRODUCT(DCF!$D$13:$H$13/(1+$B11)^DCF!$D$18:$H$18)+DCF!$C$25*(1+D$10)/($B11-D$10)/(1+$B11)^DCF!$C$30+DCF!$C$35)/DCF!$C$37) -> 38.113397 | E11: =IF(OR($B11<=E$10,DCF!$C$37=0),0,(SUMPRODUCT(DCF!$D$13:$H$13/(1+$B11)^DCF!$D$18:$H$18)+DCF!$C$25*(1+E$10)/($B11-E$10)/(1+$B11)^DCF!$C$30+DCF!$C$35)/DCF!$C$37) -> 41.008822 | F11: =IF(OR($B11<=F$10,DCF!$C$37=0),0,(SUMPRODUCT(DCF!$D$13:$H$13/(1+$B11)^DCF!$D$18:$H$18)+DCF!$C$25*(1+F$10)/($B11-F$10)/(1+$B11)^DCF!$C$30+DCF!$C$35)/DCF!$C$37) -> 44.433436 | G11: =IF(OR($B11<=G$10,DCF!$C$37=0),0,(SUMPRODUCT(DCF!$D$13:$H$13/(1+$B11)^DCF!$D$18:$H$18)+DCF!$C$25*(1+G$10)/($B11-G$10)/(1+$B11)^DCF!$C$30+DCF!$C$35)/DCF!$C$37) -> 48.546909
B12: =$B$13-1*$C$5 -> 0.089714286 | C12: =IF(OR($B12<=C$10,DCF!$C$37=0),0,(SUMPRODUCT(DCF!$D$13:$H$13/(1+$B12)^DCF!$D$18:$H$18)+DCF!$C$25*(1+C$10)/($B12-C$10)/(1+$B12)^DCF!$C$30+DCF!$C$35)/DCF!$C$37) -> 32.86179 | D12: =IF(OR($B12<=D$10,DCF!$C$37=0),0,(SUMPRODUCT(DCF!$D$13:$H$13/(1+$B12)^DCF!$D$18:$H$18)+DCF!$C$25*(1+D$10)/($B12-D$10)/(1+$B12)^DCF!$C$30+DCF!$C$35)/DCF!$C$37) -> 34.970788 | E12: =IF(OR($B12<=E$10,DCF!$C$37=0),0,(SUMPRODUCT(DCF!$D$13:$H$13/(1+$B12)^DCF!$D$18:$H$18)+DCF!$C$25*(1+E$10)/($B12-E$10)/(1+$B12)^DCF!$C$30+DCF!$C$35)/DCF!$C$37) -> 37.405679 | F12: =IF(OR($B12<=F$10,DCF!$C$37=0),0,(SUMPRODUCT(DCF!$D$13:$H$13/(1+$B12)^DCF!$D$18:$H$18)+DCF!$C$25*(1+F$10)/($B12-F$10)/(1+$B12)^DCF!$C$30+DCF!$C$35)/DCF!$C$37) -> 40.248327 | G12: =IF(OR($B12<=G$10,DCF!$C$37=0),0,(SUMPRODUCT(DCF!$D$13:$H$13/(1+$B12)^DCF!$D$18:$H$18)+DCF!$C$25*(1+G$10)/($B12-G$10)/(1+$B12)^DCF!$C$30+DCF!$C$35)/DCF!$C$37) -> 43.610519
B13: =DCF!$C$16 -> 0.094714286 | C13: =IF(OR($B13<=C$10,DCF!$C$37=0),0,(SUMPRODUCT(DCF!$D$13:$H$13/(1+$B13)^DCF!$D$18:$H$18)+DCF!$C$25*(1+C$10)/($B13-C$10)/(1+$B13)^DCF!$C$30+DCF!$C$35)/DCF!$C$37) -> 30.441 | D13: =IF(OR($B13<=D$10,DCF!$C$37=0),0,(SUMPRODUCT(DCF!$D$13:$H$13/(1+$B13)^DCF!$D$18:$H$18)+DCF!$C$25*(1+D$10)/($B13-D$10)/(1+$B13)^DCF!$C$30+DCF!$C$35)/DCF!$C$37) -> 32.251961 | E13: =IF(OR($B13<=E$10,DCF!$C$37=0),0,(SUMPRODUCT(DCF!$D$13:$H$13/(1+$B13)^DCF!$D$18:$H$18)+DCF!$C$25*(1+E$10)/($B13-E$10)/(1+$B13)^DCF!$C$30+DCF!$C$35)/DCF!$C$37) -> 34.322691 | F13: =IF(OR($B13<=F$10,DCF!$C$37=0),0,(SUMPRODUCT(DCF!$D$13:$H$13/(1+$B13)^DCF!$D$18:$H$18)+DCF!$C$25*(1+F$10)/($B13-F$10)/(1+$B13)^DCF!$C$30+DCF!$C$35)/DCF!$C$37) -> 36.713401 | G13: =IF(OR($B13<=G$10,DCF!$C$37=0),0,(SUMPRODUCT(DCF!$D$13:$H$13/(1+$B13)^DCF!$D$18:$H$18)+DCF!$C$25*(1+G$10)/($B13-G$10)/(1+$B13)^DCF!$C$30+DCF!$C$35)/DCF!$C$37) -> 39.50447
B14: =$B$13+1*$C$5 -> 0.099714286 | C14: =IF(OR($B14<=C$10,DCF!$C$37=0),0,(SUMPRODUCT(DCF!$D$13:$H$13/(1+$B14)^DCF!$D$18:$H$18)+DCF!$C$25*(1+C$10)/($B14-C$10)/(1+$B14)^DCF!$C$30+DCF!$C$35)/DCF!$C$37) -> 28.308714 | D14: =IF(OR($B14<=D$10,DCF!$C$37=0),0,(SUMPRODUCT(DCF!$D$13:$H$13/(1+$B14)^DCF!$D$18:$H$18)+DCF!$C$25*(1+D$10)/($B14-D$10)/(1+$B14)^DCF!$C$30+DCF!$C$35)/DCF!$C$37) -> 29.877053 | E14: =IF(OR($B14<=E$10,DCF!$C$37=0),0,(SUMPRODUCT(DCF!$D$13:$H$13/(1+$B14)^DCF!$D$18:$H$18)+DCF!$C$25*(1+E$10)/($B14-E$10)/(1+$B14)^DCF!$C$30+DCF!$C$35)/DCF!$C$37) -> 31.655303 | F14: =IF(OR($B14<=F$10,DCF!$C$37=0),0,(SUMPRODUCT(DCF!$D$13:$H$13/(1+$B14)^DCF!$D$18:$H$18)+DCF!$C$25*(1+F$10)/($B14-F$10)/(1+$B14)^DCF!$C$30+DCF!$C$35)/DCF!$C$37) -> 33.68863 | G14: =IF(OR($B14<=G$10,DCF!$C$37=0),0,(SUMPRODUCT(DCF!$D$13:$H$13/(1+$B14)^DCF!$D$18:$H$18)+DCF!$C$25*(1+G$10)/($B14-G$10)/(1+$B14)^DCF!$C$30+DCF!$C$35)/DCF!$C$37) -> 36.036157
B15: =$B$13+2*$C$5 -> 0.10471429 | C15: =IF(OR($B15<=C$10,DCF!$C$37=0),0,(SUMPRODUCT(DCF!$D$13:$H$13/(1+$B15)^DCF!$D$18:$H$18)+DCF!$C$25*(1+C$10)/($B15-C$10)/(1+$B15)^DCF!$C$30+DCF!$C$35)/DCF!$C$37) -> 26.416594 | D15: =IF(OR($B15<=D$10,DCF!$C$37=0),0,(SUMPRODUCT(DCF!$D$13:$H$13/(1+$B15)^DCF!$D$18:$H$18)+DCF!$C$25*(1+D$10)/($B15-D$10)/(1+$B15)^DCF!$C$30+DCF!$C$35)/DCF!$C$37) -> 27.78506 | E15: =IF(OR($B15<=E$10,DCF!$C$37=0),0,(SUMPRODUCT(DCF!$D$13:$H$13/(1+$B15)^DCF!$D$18:$H$18)+DCF!$C$25*(1+E$10)/($B15-E$10)/(1+$B15)^DCF!$C$30+DCF!$C$35)/DCF!$C$37) -> 29.325197 | F15: =IF(OR($B15<=F$10,DCF!$C$37=0),0,(SUMPRODUCT(DCF!$D$13:$H$13/(1+$B15)^DCF!$D$18:$H$18)+DCF!$C$25*(1+F$10)/($B15-F$10)/(1+$B15)^DCF!$C$30+DCF!$C$35)/DCF!$C$37) -> 31.071471 | G15: =IF(OR($B15<=G$10,DCF!$C$37=0),0,(SUMPRODUCT(DCF!$D$13:$H$13/(1+$B15)^DCF!$D$18:$H$18)+DCF!$C$25*(1+G$10)/($B15-G$10)/(1+$B15)^DCF!$C$30+DCF!$C$35)/DCF!$C$37) -> 33.068235
B17: Implied Share Price - Exit Multiple Method: WACC vs. Exit EV/EBITDA Multiple
B18: WACC \ Exit Multiple | C18: =$E$18-2*$C$7 -> 10 | D18: =$E$18-1*$C$7 -> 11 | E18: =DCF!$D$28 -> 12 | F18: =$E$18+1*$C$7 -> 13 | G18: =$E$18+2*$C$7 -> 14
B19: =$B$21-2*$C$5 -> 0.084714286 | C19: =IF(DCF!$D$37=0,0,(SUMPRODUCT(DCF!$D$13:$H$13/(1+$B19)^DCF!$D$18:$H$18)+DCF!$D$27*C$18/(1+$B19)^DCF!$D$30+DCF!$D$35)/DCF!$D$37) -> 40.232844 | D19: =IF(DCF!$D$37=0,0,(SUMPRODUCT(DCF!$D$13:$H$13/(1+$B19)^DCF!$D$18:$H$18)+DCF!$D$27*D$18/(1+$B19)^DCF!$D$30+DCF!$D$35)/DCF!$D$37) -> 43.69645 | E19: =IF(DCF!$D$37=0,0,(SUMPRODUCT(DCF!$D$13:$H$13/(1+$B19)^DCF!$D$18:$H$18)+DCF!$D$27*E$18/(1+$B19)^DCF!$D$30+DCF!$D$35)/DCF!$D$37) -> 47.160056 | F19: =IF(DCF!$D$37=0,0,(SUMPRODUCT(DCF!$D$13:$H$13/(1+$B19)^DCF!$D$18:$H$18)+DCF!$D$27*F$18/(1+$B19)^DCF!$D$30+DCF!$D$35)/DCF!$D$37) -> 50.623662 | G19: =IF(DCF!$D$37=0,0,(SUMPRODUCT(DCF!$D$13:$H$13/(1+$B19)^DCF!$D$18:$H$18)+DCF!$D$27*G$18/(1+$B19)^DCF!$D$30+DCF!$D$35)/DCF!$D$37) -> 54.087267
B20: =$B$21-1*$C$5 -> 0.089714286 | C20: =IF(DCF!$D$37=0,0,(SUMPRODUCT(DCF!$D$13:$H$13/(1+$B20)^DCF!$D$18:$H$18)+DCF!$D$27*C$18/(1+$B20)^DCF!$D$30+DCF!$D$35)/DCF!$D$37) -> 39.321174 | D20: =IF(DCF!$D$37=0,0,(SUMPRODUCT(DCF!$D$13:$H$13/(1+$B20)^DCF!$D$18:$H$18)+DCF!$D$27*D$18/(1+$B20)^DCF!$D$30+DCF!$D$35)/DCF!$D$37) -> 42.706044 | E20: =IF(DCF!$D$37=0,0,(SUMPRODUCT(DCF!$D$13:$H$13/(1+$B20)^DCF!$D$18:$H$18)+DCF!$D$27*E$18/(1+$B20)^DCF!$D$30+DCF!$D$35)/DCF!$D$37) -> 46.090915 | F20: =IF(DCF!$D$37=0,0,(SUMPRODUCT(DCF!$D$13:$H$13/(1+$B20)^DCF!$D$18:$H$18)+DCF!$D$27*F$18/(1+$B20)^DCF!$D$30+DCF!$D$35)/DCF!$D$37) -> 49.475785 | G20: =IF(DCF!$D$37=0,0,(SUMPRODUCT(DCF!$D$13:$H$13/(1+$B20)^DCF!$D$18:$H$18)+DCF!$D$27*G$18/(1+$B20)^DCF!$D$30+DCF!$D$35)/DCF!$D$37) -> 52.860655
B21: =DCF!$C$16 -> 0.094714286 | C21: =IF(DCF!$D$37=0,0,(SUMPRODUCT(DCF!$D$13:$H$13/(1+$B21)^DCF!$D$18:$H$18)+DCF!$D$27*C$18/(1+$B21)^DCF!$D$30+DCF!$D$35)/DCF!$D$37) -> 38.433303 | D21: =IF(DCF!$D$37=0,0,(SUMPRODUCT(DCF!$D$13:$H$13/(1+$B21)^DCF!$D$18:$H$18)+DCF!$D$27*D$18/(1+$B21)^DCF!$D$30+DCF!$D$35)/DCF!$D$37) -> 41.741576 | E21: =IF(DCF!$D$37=0,0,(SUMPRODUCT(DCF!$D$13:$H$13/(1+$B21)^DCF!$D$18:$H$18)+DCF!$D$27*E$18/(1+$B21)^DCF!$D$30+DCF!$D$35)/DCF!$D$37) -> 45.049849 | F21: =IF(DCF!$D$37=0,0,(SUMPRODUCT(DCF!$D$13:$H$13/(1+$B21)^DCF!$D$18:$H$18)+DCF!$D$27*F$18/(1+$B21)^DCF!$D$30+DCF!$D$35)/DCF!$D$37) -> 48.358122 | G21: =IF(DCF!$D$37=0,0,(SUMPRODUCT(DCF!$D$13:$H$13/(1+$B21)^DCF!$D$18:$H$18)+DCF!$D$27*G$18/(1+$B21)^DCF!$D$30+DCF!$D$35)/DCF!$D$37) -> 51.666395
B22: =$B$21+1*$C$5 -> 0.099714286 | C22: =IF(DCF!$D$37=0,0,(SUMPRODUCT(DCF!$D$13:$H$13/(1+$B22)^DCF!$D$18:$H$18)+DCF!$D$27*C$18/(1+$B22)^DCF!$D$30+DCF!$D$35)/DCF!$D$37) -> 37.568497 | D22: =IF(DCF!$D$37=0,0,(SUMPRODUCT(DCF!$D$13:$H$13/(1+$B22)^DCF!$D$18:$H$18)+DCF!$D$27*D$18/(1+$B22)^DCF!$D$30+DCF!$D$35)/DCF!$D$37) -> 40.802243 | E22: =IF(DCF!$D$37=0,0,(SUMPRODUCT(DCF!$D$13:$H$13/(1+$B22)^DCF!$D$18:$H$18)+DCF!$D$27*E$18/(1+$B22)^DCF!$D$30+DCF!$D$35)/DCF!$D$37) -> 44.035989 | F22: =IF(DCF!$D$37=0,0,(SUMPRODUCT(DCF!$D$13:$H$13/(1+$B22)^DCF!$D$18:$H$18)+DCF!$D$27*F$18/(1+$B22)^DCF!$D$30+DCF!$D$35)/DCF!$D$37) -> 47.269736 | G22: =IF(DCF!$D$37=0,0,(SUMPRODUCT(DCF!$D$13:$H$13/(1+$B22)^DCF!$D$18:$H$18)+DCF!$D$27*G$18/(1+$B22)^DCF!$D$30+DCF!$D$35)/DCF!$D$37) -> 50.503482
B23: =$B$21+2*$C$5 -> 0.10471429 | C23: =IF(DCF!$D$37=0,0,(SUMPRODUCT(DCF!$D$13:$H$13/(1+$B23)^DCF!$D$18:$H$18)+DCF!$D$27*C$18/(1+$B23)^DCF!$D$30+DCF!$D$35)/DCF!$D$37) -> 36.726046 | D23: =IF(DCF!$D$37=0,0,(SUMPRODUCT(DCF!$D$13:$H$13/(1+$B23)^DCF!$D$18:$H$18)+DCF!$D$27*D$18/(1+$B23)^DCF!$D$30+DCF!$D$35)/DCF!$D$37) -> 39.88727 | E23: =IF(DCF!$D$37=0,0,(SUMPRODUCT(DCF!$D$13:$H$13/(1+$B23)^DCF!$D$18:$H$18)+DCF!$D$27*E$18/(1+$B23)^DCF!$D$30+DCF!$D$35)/DCF!$D$37) -> 43.048495 | F23: =IF(DCF!$D$37=0,0,(SUMPRODUCT(DCF!$D$13:$H$13/(1+$B23)^DCF!$D$18:$H$18)+DCF!$D$27*F$18/(1+$B23)^DCF!$D$30+DCF!$D$35)/DCF!$D$37) -> 46.20972 | G23: =IF(DCF!$D$37=0,0,(SUMPRODUCT(DCF!$D$13:$H$13/(1+$B23)^DCF!$D$18:$H$18)+DCF!$D$27*G$18/(1+$B23)^DCF!$D$30+DCF!$D$35)/DCF!$D$37) -> 49.370945

Sheet Comps
B1: =CompanyName&" - Comparable Companies Analysis" -> Example Co. - Comparable Companies Analysis
B2: ="("&Units&" except per-share data; peer data is hand-entered in blue)" -> ($ in millions except per-share data; peer data is hand-entered in blue)
B4: Peer Inputs
B5: Company | C5: Ticker | D5: Share Price ($) | E5: Diluted Shares (mm) | F5: Market Cap ($mm) | G5: Net Debt ($mm) | H5: Enterprise Value ($mm) | I5: LTM Revenue | J5: NTM Revenue | K5: LTM EBITDA | L5: NTM EBITDA | M5: LTM EBIT | N5: NTM EBIT | O5: LTM EPS ($) | P5: NTM EPS ($) | Q5: Source / As-of Date
B6: Peer Company 1 | C6: PEER1 | D6: 52 | E6: 120 | F6: =IF(AND(ISNUMBER(D6),ISNUMBER(E6)),D6*E6,"") -> 6240 | G6: 600 | H6: =IF(AND(ISNUMBER(F6),ISNUMBER(G6)),F6+G6,"") -> 6840 | I6: 1800 | J6: 1930 | K6: 560 | L6: 610 | M6: 430 | N6: 470 | O6: 2.4 | P6: 2.65 | Q6: Placeholder - replace (source, as-of date)
B7: Peer Company 2 | C7: PEER2 | D7: 88.5 | E7: 85 | F7: =IF(AND(ISNUMBER(D7),ISNUMBER(E7)),D7*E7,"") -> 7522.5 | G7: 1200 | H7: =IF(AND(ISNUMBER(F7),ISNUMBER(G7)),F7+G7,"") -> 8722.5 | I7: 3100 | J7: 3300 | K7: 900 | L7: 980 | M7: 700 | N7: 765 | O7: 5.1 | P7: 5.6 | Q7: Placeholder - replace (source, as-of date)
B8: Peer Company 3 | C8: PEER3 | D8: 34.25 | E8: 210 | F8: =IF(AND(ISNUMBER(D8),ISNUMBER(E8)),D8*E8,"") -> 7192.5 | G8: 300 | H8: =IF(AND(ISNUMBER(F8),ISNUMBER(G8)),F8+G8,"") -> 7492.5 | I8: 2500 | J8: 2700 | K8: 650 | L8: 720 | M8: 480 | N8: 540 | O8: 1.55 | P8: 1.75 | Q8: Placeholder - replace (source, as-of date)
B9: Peer Company 4 | C9: PEER4 | D9: 120 | E9: 60 | F9: =IF(AND(ISNUMBER(D9),ISNUMBER(E9)),D9*E9,"") -> 7200 | G9: -250 | H9: =IF(AND(ISNUMBER(F9),ISNUMBER(G9)),F9+G9,"") -> 6950 | I9: 1500 | J9: 1650 | K9: 520 | L9: 575 | M9: 410 | N9: 455 | O9: 5.2 | P9: 5.8 | Q9: Placeholder - replace (source, as-of date)
B10: Peer Company 5 | C10: PEER5 | D10: 45.75 | E10: 150 | F10: =IF(AND(ISNUMBER(D10),ISNUMBER(E10)),D10*E10,"") -> 6862.5 | G10: 900 | H10: =IF(AND(ISNUMBER(F10),ISNUMBER(G10)),F10+G10,"") -> 7762.5 | I10: 2200 | J10: 2330 | K10: 600 | L10: 640 | M10: 450 | N10: 485 | O10: 2.05 | P10: 2.25 | Q10: Placeholder - replace (source, as-of date)
B11: Peer Company 6 | C11: PEER6 | D11: 18.4 | E11: 400 | F11: =IF(AND(ISNUMBER(D11),ISNUMBER(E11)),D11*E11,"") -> 7360 | G11: 2500 | H11: =IF(AND(ISNUMBER(F11),ISNUMBER(G11)),F11+G11,"") -> 9860 | I11: 4200 | J11: 4350 | K11: 700 | L11: 760 | M11: 380 | N11: 420 | O11: 0.55 | P11: 0.68 | Q11: Placeholder - replace (source, as-of date)
F12: =IF(AND(ISNUMBER(D12),ISNUMBER(E12)),D12*E12,"") | H12: =IF(AND(ISNUMBER(F12),ISNUMBER(G12)),F12+G12,"")
F13: =IF(AND(ISNUMBER(D13),ISNUMBER(E13)),D13*E13,"") | H13: =IF(AND(ISNUMBER(F13),ISNUMBER(G13)),F13+G13,"")
B15: Peer Multiples
B16: Company | C16: Ticker | D16: Include (1/0) | E16: EV/Revenue - LTM | F16: EV/Revenue - NTM | G16: EV/EBITDA - LTM | H16: EV/EBITDA - NTM | I16: EV/EBIT - LTM | J16: EV/EBIT - NTM | K16: P/E - LTM | L16: P/E - NTM
B17: =IF(B6="","",B6) -> Peer Company 1 | C17: =IF(C6="","",C6) -> PEER1 | D17: 1 | E17: =IFERROR($H6/I6,"") -> 3.8 | F17: =IFERROR($H6/J6,"") -> 3.5440415 | G17: =IFERROR($H6/K6,"") -> 12.214286 | H17: =IFERROR($H6/L6,"") -> 11.213115 | I17: =IFERROR($H6/M6,"") -> 15.906977 | J17: =IFERROR($H6/N6,"") -> 14.553191 | K17: =IFERROR(IF(ISNUMBER($D6),$D6/O6,""),"") -> 21.666667 | L17: =IFERROR(IF(ISNUMBER($D6),$D6/P6,""),"") -> 19.622642
B18: =IF(B7="","",B7) -> Peer Company 2 | C18: =IF(C7="","",C7) -> PEER2 | D18: 1 | E18: =IFERROR($H7/I7,"") -> 2.8137097 | F18: =IFERROR($H7/J7,"") -> 2.6431818 | G18: =IFERROR($H7/K7,"") -> 9.6916667 | H18: =IFERROR($H7/L7,"") -> 8.9005102 | I18: =IFERROR($H7/M7,"") -> 12.460714 | J18: =IFERROR($H7/N7,"") -> 11.401961 | K18: =IFERROR(IF(ISNUMBER($D7),$D7/O7,""),"") -> 17.352941 | L18: =IFERROR(IF(ISNUMBER($D7),$D7/P7,""),"") -> 15.803571
B19: =IF(B8="","",B8) -> Peer Company 3 | C19: =IF(C8="","",C8) -> PEER3 | D19: 1 | E19: =IFERROR($H8/I8,"") -> 2.997 | F19: =IFERROR($H8/J8,"") -> 2.775 | G19: =IFERROR($H8/K8,"") -> 11.526923 | H19: =IFERROR($H8/L8,"") -> 10.40625 | I19: =IFERROR($H8/M8,"") -> 15.609375 | J19: =IFERROR($H8/N8,"") -> 13.875 | K19: =IFERROR(IF(ISNUMBER($D8),$D8/O8,""),"") -> 22.096774 | L19: =IFERROR(IF(ISNUMBER($D8),$D8/P8,""),"") -> 19.571429
B20: =IF(B9="","",B9) -> Peer Company 4 | C20: =IF(C9="","",C9) -> PEER4 | D20: 1 | E20: =IFERROR($H9/I9,"") -> 4.6333333 | F20: =IFERROR($H9/J9,"") -> 4.2121212 | G20: =IFERROR($H9/K9,"") -> 13.365385 | H20: =IFERROR($H9/L9,"") -> 12.086957 | I20: =IFERROR($H9/M9,"") -> 16.95122 | J20: =IFERROR($H9/N9,"") -> 15.274725 | K20: =IFERROR(IF(ISNUMBER($D9),$D9/O9,""),"") -> 23.076923 | L20: =IFERROR(IF(ISNUMBER($D9),$D9/P9,""),"") -> 20.689655
B21: =IF(B10="","",B10) -> Peer Company 5 | C21: =IF(C10="","",C10) -> PEER5 | D21: 1 | E21: =IFERROR($H10/I10,"") -> 3.5284091 | F21: =IFERROR($H10/J10,"") -> 3.3315451 | G21: =IFERROR($H10/K10,"") -> 12.9375 | H21: =IFERROR($H10/L10,"") -> 12.128906 | I21: =IFERROR($H10/M10,"") -> 17.25 | J21: =IFERROR($H10/N10,"") -> 16.005155 | K21: =IFERROR(IF(ISNUMBER($D10),$D10/O10,""),"") -> 22.317073 | L21: =IFERROR(IF(ISNUMBER($D10),$D10/P10,""),"") -> 20.333333
B22: =IF(B11="","",B11) -> Peer Company 6 | C22: =IF(C11="","",C11) -> PEER6 | D22: 1 | E22: =IFERROR($H11/I11,"") -> 2.347619 | F22: =IFERROR($H11/J11,"") -> 2.2666667 | G22: =IFERROR($H11/K11,"") -> 14.085714 | H22: =IFERROR($H11/L11,"") -> 12.973684 | I22: =IFERROR($H11/M11,"") -> 25.947368 | J22: =IFERROR($H11/N11,"") -> 23.47619 | K22: =IFERROR(IF(ISNUMBER($D11),$D11/O11,""),"") -> 33.454545 | L22: =IFERROR(IF(ISNUMBER($D11),$D11/P11,""),"") -> 27.058824
B23: =IF(B12="","",B12) | C23: =IF(C12="","",C12) | D23: 1 | E23: =IFERROR($H12/I12,"") | F23: =IFERROR($H12/J12,"") | G23: =IFERROR($H12/K12,"") | H23: =IFERROR($H12/L12,"") | I23: =IFERROR($H12/M12,"") | J23: =IFERROR($H12/N12,"") | K23: =IFERROR(IF(ISNUMBER($D12),$D12/O12,""),"") | L23: =IFERROR(IF(ISNUMBER($D12),$D12/P12,""),"")
B24: =IF(B13="","",B13) | C24: =IF(C13="","",C13) | D24: 1 | E24: =IFERROR($H13/I13,"") | F24: =IFERROR($H13/J13,"") | G24: =IFERROR($H13/K13,"") | H24: =IFERROR($H13/L13,"") | I24: =IFERROR($H13/M13,"") | J24: =IFERROR($H13/N13,"") | K24: =IFERROR(IF(ISNUMBER($D13),$D13/O13,""),"") | L24: =IFERROR(IF(ISNUMBER($D13),$D13/P13,""),"")
B26: Statistics (included peers only)
B27: Statistic | E27: EV/Revenue - LTM | F27: EV/Revenue - NTM | G27: EV/EBITDA - LTM | H27: EV/EBITDA - NTM | I27: EV/EBIT - LTM | J27: EV/EBIT - NTM | K27: P/E - LTM | L27: P/E - NTM
B28: Mean | E28: =IF(COUNT(E$37:E$44)=0,"",AVERAGE(E$37:E$44)) -> 3.3533452 | F28: =IF(COUNT(F$37:F$44)=0,"",AVERAGE(F$37:F$44)) -> 3.1287594 | G28: =IF(COUNT(G$37:G$44)=0,"",AVERAGE(G$37:G$44)) -> 12.303579 | H28: =IF(COUNT(H$37:H$44)=0,"",AVERAGE(H$37:H$44)) -> 11.284904 | I28: =IF(COUNT(I$37:I$44)=0,"",AVERAGE(I$37:I$44)) -> 17.354276 | J28: =IF(COUNT(J$37:J$44)=0,"",AVERAGE(J$37:J$44)) -> 15.76437 | K28: =IF(COUNT(K$37:K$44)=0,"",AVERAGE(K$37:K$44)) -> 23.327487 | L28: =IF(COUNT(L$37:L$44)=0,"",AVERAGE(L$37:L$44)) -> 20.513242
B29: Median | E29: =IF(COUNT(E$37:E$44)=0,"",MEDIAN(E$37:E$44)) -> 3.2627045 | F29: =IF(COUNT(F$37:F$44)=0,"",MEDIAN(F$37:F$44)) -> 3.0532725 | G29: =IF(COUNT(G$37:G$44)=0,"",MEDIAN(G$37:G$44)) -> 12.575893 | H29: =IF(COUNT(H$37:H$44)=0,"",MEDIAN(H$37:H$44)) -> 11.650036 | I29: =IF(COUNT(I$37:I$44)=0,"",MEDIAN(I$37:I$44)) -> 16.429098 | J29: =IF(COUNT(J$37:J$44)=0,"",MEDIAN(J$37:J$44)) -> 14.913958 | K29: =IF(COUNT(K$37:K$44)=0,"",MEDIAN(K$37:K$44)) -> 22.206924 | L29: =IF(COUNT(L$37:L$44)=0,"",MEDIAN(L$37:L$44)) -> 19.977987
B30: High | E30: =IF(COUNT(E$37:E$44)=0,"",MAX(E$37:E$44)) -> 4.6333333 | F30: =IF(COUNT(F$37:F$44)=0,"",MAX(F$37:F$44)) -> 4.2121212 | G30: =IF(COUNT(G$37:G$44)=0,"",MAX(G$37:G$44)) -> 14.085714 | H30: =IF(COUNT(H$37:H$44)=0,"",MAX(H$37:H$44)) -> 12.973684 | I30: =IF(COUNT(I$37:I$44)=0,"",MAX(I$37:I$44)) -> 25.947368 | J30: =IF(COUNT(J$37:J$44)=0,"",MAX(J$37:J$44)) -> 23.47619 | K30: =IF(COUNT(K$37:K$44)=0,"",MAX(K$37:K$44)) -> 33.454545 | L30: =IF(COUNT(L$37:L$44)=0,"",MAX(L$37:L$44)) -> 27.058824
B31: Low | E31: =IF(COUNT(E$37:E$44)=0,"",MIN(E$37:E$44)) -> 2.347619 | F31: =IF(COUNT(F$37:F$44)=0,"",MIN(F$37:F$44)) -> 2.2666667 | G31: =IF(COUNT(G$37:G$44)=0,"",MIN(G$37:G$44)) -> 9.6916667 | H31: =IF(COUNT(H$37:H$44)=0,"",MIN(H$37:H$44)) -> 8.9005102 | I31: =IF(COUNT(I$37:I$44)=0,"",MIN(I$37:I$44)) -> 12.460714 | J31: =IF(COUNT(J$37:J$44)=0,"",MIN(J$37:J$44)) -> 11.401961 | K31: =IF(COUNT(K$37:K$44)=0,"",MIN(K$37:K$44)) -> 17.352941 | L31: =IF(COUNT(L$37:L$44)=0,"",MIN(L$37:L$44)) -> 15.803571
B32: 25th Percentile | E32: =IF(COUNT(E$37:E$44)=0,"",PERCENTILE(E$37:E$44,0.25)) -> 2.8595323 | F32: =IF(COUNT(F$37:F$44)=0,"",PERCENTILE(F$37:F$44,0.25)) -> 2.6761364 | G32: =IF(COUNT(G$37:G$44)=0,"",PERCENTILE(G$37:G$44,0.25)) -> 11.698764 | H32: =IF(COUNT(H$37:H$44)=0,"",PERCENTILE(H$37:H$44,0.25)) -> 10.607966 | I32: =IF(COUNT(I$37:I$44)=0,"",PERCENTILE(I$37:I$44,0.25)) -> 15.683775 | J32: =IF(COUNT(J$37:J$44)=0,"",PERCENTILE(J$37:J$44,0.25)) -> 14.044548 | K32: =IF(COUNT(K$37:K$44)=0,"",PERCENTILE(K$37:K$44,0.25)) -> 21.774194 | L32: =IF(COUNT(L$37:L$44)=0,"",PERCENTILE(L$37:L$44,0.25)) -> 19.584232
B33: 75th Percentile | E33: =IF(COUNT(E$37:E$44)=0,"",PERCENTILE(E$37:E$44,0.75)) -> 3.7321023 | F33: =IF(COUNT(F$37:F$44)=0,"",PERCENTILE(F$37:F$44,0.75)) -> 3.4909174 | G33: =IF(COUNT(G$37:G$44)=0,"",PERCENTILE(G$37:G$44,0.75)) -> 13.258413 | H33: =IF(COUNT(H$37:H$44)=0,"",PERCENTILE(H$37:H$44,0.75)) -> 12.118419 | I33: =IF(COUNT(I$37:I$44)=0,"",PERCENTILE(I$37:I$44,0.75)) -> 17.175305 | J33: =IF(COUNT(J$37:J$44)=0,"",PERCENTILE(J$37:J$44,0.75)) -> 15.822547 | K33: =IF(COUNT(K$37:K$44)=0,"",PERCENTILE(K$37:K$44,0.75)) -> 22.886961 | L33: =IF(COUNT(L$37:L$44)=0,"",PERCENTILE(L$37:L$44,0.75)) -> 20.600575
B35: Multiples Used in Statistics (multiple if Include = 1, else blank)
B36: Company | C36: Ticker | D36: Include (1/0) | E36: EV/Revenue - LTM | F36: EV/Revenue - NTM | G36: EV/EBITDA - LTM | H36: EV/EBITDA - NTM | I36: EV/EBIT - LTM | J36: EV/EBIT - NTM | K36: P/E - LTM | L36: P/E - NTM
B37: =B17 -> Peer Company 1 | C37: =C17 -> PEER1 | D37: =D17 -> 1 | E37: =IF(AND($D17=1,ISNUMBER(E17)),E17,"") -> 3.8 | F37: =IF(AND($D17=1,ISNUMBER(F17)),F17,"") -> 3.5440415 | G37: =IF(AND($D17=1,ISNUMBER(G17)),G17,"") -> 12.214286 | H37: =IF(AND($D17=1,ISNUMBER(H17)),H17,"") -> 11.213115 | I37: =IF(AND($D17=1,ISNUMBER(I17)),I17,"") -> 15.906977 | J37: =IF(AND($D17=1,ISNUMBER(J17)),J17,"") -> 14.553191 | K37: =IF(AND($D17=1,ISNUMBER(K17)),K17,"") -> 21.666667 | L37: =IF(AND($D17=1,ISNUMBER(L17)),L17,"") -> 19.622642
B38: =B18 -> Peer Company 2 | C38: =C18 -> PEER2 | D38: =D18 -> 1 | E38: =IF(AND($D18=1,ISNUMBER(E18)),E18,"") -> 2.8137097 | F38: =IF(AND($D18=1,ISNUMBER(F18)),F18,"") -> 2.6431818 | G38: =IF(AND($D18=1,ISNUMBER(G18)),G18,"") -> 9.6916667 | H38: =IF(AND($D18=1,ISNUMBER(H18)),H18,"") -> 8.9005102 | I38: =IF(AND($D18=1,ISNUMBER(I18)),I18,"") -> 12.460714 | J38: =IF(AND($D18=1,ISNUMBER(J18)),J18,"") -> 11.401961 | K38: =IF(AND($D18=1,ISNUMBER(K18)),K18,"") -> 17.352941 | L38: =IF(AND($D18=1,ISNUMBER(L18)),L18,"") -> 15.803571
B39: =B19 -> Peer Company 3 | C39: =C19 -> PEER3 | D39: =D19 -> 1 | E39: =IF(AND($D19=1,ISNUMBER(E19)),E19,"") -> 2.997 | F39: =IF(AND($D19=1,ISNUMBER(F19)),F19,"") -> 2.775 | G39: =IF(AND($D19=1,ISNUMBER(G19)),G19,"") -> 11.526923 | H39: =IF(AND($D19=1,ISNUMBER(H19)),H19,"") -> 10.40625 | I39: =IF(AND($D19=1,ISNUMBER(I19)),I19,"") -> 15.609375 | J39: =IF(AND($D19=1,ISNUMBER(J19)),J19,"") -> 13.875 | K39: =IF(AND($D19=1,ISNUMBER(K19)),K19,"") -> 22.096774 | L39: =IF(AND($D19=1,ISNUMBER(L19)),L19,"") -> 19.571429
B40: =B20 -> Peer Company 4 | C40: =C20 -> PEER4 | D40: =D20 -> 1 | E40: =IF(AND($D20=1,ISNUMBER(E20)),E20,"") -> 4.6333333 | F40: =IF(AND($D20=1,ISNUMBER(F20)),F20,"") -> 4.2121212 | G40: =IF(AND($D20=1,ISNUMBER(G20)),G20,"") -> 13.365385 | H40: =IF(AND($D20=1,ISNUMBER(H20)),H20,"") -> 12.086957 | I40: =IF(AND($D20=1,ISNUMBER(I20)),I20,"") -> 16.95122 | J40: =IF(AND($D20=1,ISNUMBER(J20)),J20,"") -> 15.274725 | K40: =IF(AND($D20=1,ISNUMBER(K20)),K20,"") -> 23.076923 | L40: =IF(AND($D20=1,ISNUMBER(L20)),L20,"") -> 20.689655
B41: =B21 -> Peer Company 5 | C41: =C21 -> PEER5 | D41: =D21 -> 1 | E41: =IF(AND($D21=1,ISNUMBER(E21)),E21,"") -> 3.5284091 | F41: =IF(AND($D21=1,ISNUMBER(F21)),F21,"") -> 3.3315451 | G41: =IF(AND($D21=1,ISNUMBER(G21)),G21,"") -> 12.9375 | H41: =IF(AND($D21=1,ISNUMBER(H21)),H21,"") -> 12.128906 | I41: =IF(AND($D21=1,ISNUMBER(I21)),I21,"") -> 17.25 | J41: =IF(AND($D21=1,ISNUMBER(J21)),J21,"") -> 16.005155 | K41: =IF(AND($D21=1,ISNUMBER(K21)),K21,"") -> 22.317073 | L41: =IF(AND($D21=1,ISNUMBER(L21)),L21,"") -> 20.333333
B42: =B22 -> Peer Company 6 | C42: =C22 -> PEER6 | D42: =D22 -> 1 | E42: =IF(AND($D22=1,ISNUMBER(E22)),E22,"") -> 2.347619 | F42: =IF(AND($D22=1,ISNUMBER(F22)),F22,"") -> 2.2666667 | G42: =IF(AND($D22=1,ISNUMBER(G22)),G22,"") -> 14.085714 | H42: =IF(AND($D22=1,ISNUMBER(H22)),H22,"") -> 12.973684 | I42: =IF(AND($D22=1,ISNUMBER(I22)),I22,"") -> 25.947368 | J42: =IF(AND($D22=1,ISNUMBER(J22)),J22,"") -> 23.47619 | K42: =IF(AND($D22=1,ISNUMBER(K22)),K22,"") -> 33.454545 | L42: =IF(AND($D22=1,ISNUMBER(L22)),L22,"") -> 27.058824
B43: =B23 | C43: =C23 | D43: =D23 -> 1 | E43: =IF(AND($D23=1,ISNUMBER(E23)),E23,"") | F43: =IF(AND($D23=1,ISNUMBER(F23)),F23,"") | G43: =IF(AND($D23=1,ISNUMBER(G23)),G23,"") | H43: =IF(AND($D23=1,ISNUMBER(H23)),H23,"") | I43: =IF(AND($D23=1,ISNUMBER(I23)),I23,"") | J43: =IF(AND($D23=1,ISNUMBER(J23)),J23,"") | K43: =IF(AND($D23=1,ISNUMBER(K23)),K23,"") | L43: =IF(AND($D23=1,ISNUMBER(L23)),L23,"")
B44: =B24 | C44: =C24 | D44: =D24 -> 1 | E44: =IF(AND($D24=1,ISNUMBER(E24)),E24,"") | F44: =IF(AND($D24=1,ISNUMBER(F24)),F24,"") | G44: =IF(AND($D24=1,ISNUMBER(G24)),G24,"") | H44: =IF(AND($D24=1,ISNUMBER(H24)),H24,"") | I44: =IF(AND($D24=1,ISNUMBER(I24)),I24,"") | J44: =IF(AND($D24=1,ISNUMBER(J24)),J24,"") | K44: =IF(AND($D24=1,ISNUMBER(K24)),K24,"") | L44: =IF(AND($D24=1,ISNUMBER(L24)),L24,"")
...
